<?xml version="1.0"?>
<robot name="minirys" xmlns:xacro="http://ros.org/wiki/xacro">

  <!-- Define robot constants -->
  <xacro:property name="wheel_radius" value="0.055"/>
  <xacro:property name="body_mass" value="1.16182"/>
  <xacro:property name="wheel_mass" value="0.170328"/>
  <xacro:property name="wheel_yoff" value="0.069"/>

  <!-- Robot Base -->

  <link name="base_link">
      <visual name="visual">
        <box size="0.01 0.01 0.01"/>
        <material name="black" >
          <color rgba="0.0 0.0 0.0 1.0" />
        </material>
      </visual>

    </link>

  <link name="robot_base">
    <origin xyz="0 0 0" rpy="0 0 0"/>
    <inertial>
      <mass value="${body_mass}"/>
      <origin xyz="0.033152 0.000109 0" rpy="1.5708 1.5708 0"/>
      <inertia ixx="0.00177719" ixy="0" ixz="0" iyy="0.00211063" iyz="0" izz="0.002939"/>
    </inertial>

    <visual>
      <origin xyz="0 0 0" rpy="0 1.5708 0"/>
      <geometry>
        <mesh filename="package://minirys_description/src/description/stl/irys5.STL"/>
      </geometry>
      <material name="charcoalgrey" >
        <color rgba="0.23529411764705882 0.2549019607843137 0.25882352941176473 1.0" />
      </material>
    </visual>

    <collision>
      <origin xyz="0.04 0 0" rpy="0 1.5708 0"/>
      <geometry>
        <box size="0.07 0.116 0.13"/>
      </geometry>
    </collision>

    <collision>
      <origin xyz="0.09 0 0" rpy="0 1.5708 0"/>
      <geometry>
        <cylinder radius="0.067" length="0.01"/>
      </geometry>
    </collision>

      <collision>
        <origin xyz="-0.034 0 0" rpy="1.5708 1.5708 0"/>
        <geometry>
          <cylinder radius="0.01" length="0.071"/>
        </geometry>
      </collision>

      <collision>
        <origin xyz="0.11 0 0" rpy="1.5708 1.5708 0"/>
        <geometry>
          <cylinder radius="0.034" length="0.06"/>
        </geometry>
      </collision>
  </link>

  <joint name="robot_base_joint" type="fixed">
        <parent link="base_link"/>
        <child link="robot_base"/>
        <origin xyz="0 0 0" rpy="0 0 0"/>
  </joint>

  <link name="robot_frame">
    <origin xyz="0 0 0" rpy="0 0 0"/>

    <visual>
      <origin xyz="0 0 0" rpy="0 -1.5708 3.14159"/>
      <geometry>
        <mesh filename="package://minirys_description/src/description/stl/frame_coordinate_system.STL"/>
      </geometry>
      <material name="deeporange" >
        <color rgba="0.8627450980392157 0.30196078431372547 0.00392156862745098 1.0" />
      </material>
    </visual>

  </link>

  <joint name="base_frame_joint" type="fixed">
          <parent link="robot_base"/>
          <child link="robot_frame"/>
          <origin xyz="0 0 0" rpy="0 0 0"/>
    </joint>

  <!-- Robot Footprint -->
    <link name="base_footprint"/>
    <joint name="base_joint" type="fixed">
      <parent link="base_link"/>
      <child link="base_footprint"/>
      <origin xyz="0.0 0.0 ${-wheel_radius}" rpy="0 0 0"/>
    </joint>

  <!-- Wheels -->

  <link name="leftwheel">
    <origin xyz="0 0 0" rpy="0 0 0"/>
    <inertial>
      <mass value="${wheel_mass}"/>
      <origin xyz="0 0 0" rpy="0 0 0"/>
      <inertia ixx="0.00013418" ixy="0" ixz="0" iyy="0.00026198" iyz="0" izz="0.00013418"/>
    </inertial>

    <visual name="visual">
      <origin xyz="0 -0.007 0" rpy="0 0 3.14159"/>
      <geometry>
        <mesh filename="package://minirys_description/src/description/stl/wheelpop.STL"/>
      </geometry>
      <material name="charcoalgrey" >
        <color rgba="0.23529411764705882 0.2549019607843137 0.25882352941176473 1.0" />
      </material>
    </visual>

    <collision>
      <origin xyz="0 0 0" rpy="1.5708 0 0"/>
      <geometry>
        <cylinder radius="0.055463" length="0.015"/>
      </geometry>
    </collision>
  </link>

  <link name="rightwheel">
    <origin xyz="0 0 0" rpy="0 0 0"/>
    <inertial>
      <mass value="${wheel_mass}"/>
      <origin xyz="0 0 0" rpy="0 0 0"/>
      <inertia ixx="0.00013418" ixy="0" ixz="0" iyy="0.00026198" iyz="0" izz="0.00013418"/>
    </inertial>

    <visual name="visual">
      <origin xyz="0 -0.007 0" rpy="0 0 3.14159"/>
      <geometry>
        <mesh filename="package://minirys_description/src/description/stl/wheelpop.STL"/>
      </geometry>
      <material name="charcoalgrey" >
        <color rgba="0.23529411764705882 0.2549019607843137 0.25882352941176473 1.0" />
      </material>
    </visual>

    <collision>
      <origin xyz="0 0 0" rpy="1.5708 0 0"/>
      <geometry>
        <cylinder radius="0.055463" length="0.015"/>
      </geometry>
    </collision>
  </link>

  <joint name="base_link_to_rightwheel_joint" type="continuous">
    <parent link="base_link"/>
    <child link="rightwheel"/>
    <origin xyz="0 ${wheel_yoff} 0" rpy="0 0 3.14159"/>
    <axis xyz="0 -1 0" />
  </joint>

  <joint name="base_link_to_leftwheel_joint" type="continuous">
    <parent link="base_link"/>
    <child link="leftwheel"/>
    <origin xyz="0 -${wheel_yoff} 0" rpy="0 0 0"/>
    <axis xyz="0 -1 0" />
  </joint>

  <!-- TOF -->
  <xacro:macro name="distance" params="number">
    <link name="distance_${number}">
    <origin xyz="0 0 0" rpy="0 0 0"/>
    <visual>
      <origin xyz="0 0 0" rpy="0 0 0"/>
      <geometry>
        <box size="0.002 0.018 0.013"/>
      </geometry>
    </visual>

    <collision>
      <origin xyz="0 0 0" rpy="0 0 0"/>
      <geometry>
        <box size="0.002 0.018 0.013"/>
      </geometry>
    </collision>

    <inertial>
      <origin xyz="0 0 0" rpy="0 0 0"/>
      <mass value="0.005"/>
      <inertia ixx="0.001"  ixy="0"  ixz="0" iyy="0.001" iyz="0" izz="0.001" />
    </inertial>
    </link>
  </xacro:macro>

  <xacro:distance number="0"/>
  <xacro:distance number="1"/>
  <xacro:distance number="2"/>
  <xacro:distance number="3"/>
  <xacro:distance number="4"/>
  <xacro:distance number="5"/>

  <joint name="distance_0_joint" type="fixed">
    <parent link="robot_base"/>
    <child link="distance_0"/>
    <origin xyz="0.093 -0.040 0" rpy="0 0 0"/>
  </joint>

  <joint name="distance_1_joint" type="fixed">
    <parent link="robot_base"/>
    <child link="distance_1"/>
    <origin xyz="-0.022 0 -0.021" rpy="3.14159 0 3.14159"/>
  </joint>

  <joint name="distance_2_joint" type="fixed">
    <parent link="robot_base"/>
    <child link="distance_2"/>
    <origin xyz="0.06 0.050 0" rpy="1.5708 0 1.5708"/>
  </joint>

  <joint name="distance_3_joint" type="fixed">
    <parent link="robot_base"/>
    <child link="distance_3"/>
    <origin xyz="0.061 0 0.030" rpy="3.14159 -1.5708 0"/>
  </joint>

  <joint name="distance_4_joint" type="fixed">
    <parent link="robot_base"/>
    <child link="distance_4"/>
    <origin xyz="0.061 0 -0.030" rpy="0 1.5708 0"/>
  </joint>

  <joint name="distance_5_joint" type="fixed">
    <parent link="robot_base"/>
    <child link="distance_5"/>
    <origin xyz="0.06 -0.050 0" rpy="-1.5708 0 -1.5708"/>
  </joint>

  <!-- IMU -->
  <link name="imu">
    <origin xyz="0 0 0" rpy="0 0 0"/>
    <visual>
      <origin xyz="0 0 0" rpy="0 0 0"/>
      <geometry>
        <box size="0.003 0.010 0.023"/>
      </geometry>
    </visual>

    <collision>
      <origin xyz="0 0 0" rpy="0 0 0"/>
      <geometry>
        <box size="0.003 0.010 0.023"/>
      </geometry>
    </collision>

    <inertial>
      <origin xyz="0 0 0" rpy="0 0 0"/>
      <mass value="0.005"/>
      <inertia ixx="0.001"  ixy="0"  ixz="0" iyy="0.001" iyz="0" izz="0.001" />
    </inertial>
  </link>

  <joint name="imu_joint" type="fixed">
    <parent link="robot_base"/>
    <child link="imu"/>
    <origin xyz="0 0 0" rpy="0 0 0"/>
  </joint>

 <!-- LaserScan -->

  <link name="laser_scan">
    <origin xyz="0 0 0" rpy="0 0 0"/>
    <visual>
      <origin xyz="0 0 -0.0257" rpy="1.5708 0 0"/>
      <geometry>
        <mesh filename="package://minirys_description/src/description/stl/LD06_lidar.STL"/>
      </geometry>
      <material name="charcoalgrey" >
        <color rgba="0.23529411764705882 0.2549019607843137 0.25882352941176473 1.0" />
      </material>
    </visual>

    <collision>
      <origin xyz="0 0 0" rpy="0 0 0"/>
      <geometry>
        <box size="0.002 0.018 0.013"/>
      </geometry>
    </collision>

    <inertial>
      <origin xyz="0 0 0" rpy="0 0 0"/>
      <mass value="0.005"/>
      <inertia ixx="0.001"  ixy="0"  ixz="0" iyy="0.001" iyz="0" izz="0.001" />
    </inertial>
  </link>

  <joint name="laser_scan_joint" type="fixed">
      <parent link="robot_base"/>
      <child link="laser_scan"/>
      <origin xyz="0.044 0 0.059" rpy="0 0 0"/>
   </joint>

</robot>